<tr>
	<td>1</td>
	<td><input onchange="tqhk(2,0,&quot;table_result&quot;)" value="0.13" name="mybj1" id="mybj1" class="tbblur1"></td>
	<td><span id="mylx1" class="tbblur2">0.02</span><input type="hidden" value="0.02" name="mylx1"></td>
	<td><span id="mybx1" class="tbblur3">0.15</span><input type="hidden" value="0.15" name="mybx1"></td>
	<td><input type="text" readonly="" data-date-format="yyyy-mm-dd" class="datepicker" name="myrq1"></td>
</tr>2014-01-09 10:53:52,645 ERROR exception
Traceback (most recent call last):
  File "D:\Development\android_workspace\SC\scapp\views\information\lfdj.py", line 92, in new_lfdj
    is_need_service = request.form['is_need_service']
  File "D:\Development\android_workspace\SC\virtualenv32\lib\site-packages\werkzeug\datastructures.py", line 391, in __getitem__
    raise exceptions.BadRequestKeyError(key)
BadRequestKeyError: 400: Bad Request
2014-01-09 15:01:29,948 ERROR exception
Traceback (most recent call last):
  File "D:\Development\android_workspace\SC\scapp\views\process\dkfk.py", line 111, in edit_dkfk
    request.form['mybx%d' % i],i,request.form['myrq%d' % i],None,1).add()
  File "D:\Development\android_workspace\SC\virtualenv32\lib\site-packages\werkzeug\datastructures.py", line 391, in __getitem__
    raise exceptions.BadRequestKeyError(key)
BadRequestKeyError: 400: Bad Request
2014-01-09 15:02:54,987 ERROR exception
Traceback (most recent call last):
  File "D:\Development\android_workspace\SC\scapp\views\process\dkfk.py", line 112, in edit_dkfk
    i,request.form['myrq%d' % i],None,1).add()
  File "D:\Development\android_workspace\SC\virtualenv32\lib\site-packages\werkzeug\datastructures.py", line 391, in __getitem__
    raise exceptions.BadRequestKeyError(key)
BadRequestKeyError: 400: Bad Request
2014-01-15 14:09:51,505 ERROR exception
Traceback (most recent call last):
  File "D:\Development\android_workspace\sc\SC\scapp\views\information\khxxgl.py", line 114, in new_individual_customer
    request.form['is_otherjob'],request.form['profession'],request.form['duty'],request.form['title'],
  File "D:\Development\android_workspace\sc\SC\virtualenv32\lib\site-packages\werkzeug\datastructures.py", line 391, in __getitem__
    raise exceptions.BadRequestKeyError(key)
BadRequestKeyError: 400: Bad Request
2014-01-15 14:20:01,486 ERROR exception
Traceback (most recent call last):
  File "D:\Development\android_workspace\sc\SC\scapp\views\information\khxxgl.py", line 130, in new_individual_customer
    request.form['is_active']).add()
TypeError: __init__() takes exactly 41 arguments (42 given)
2014-01-15 14:48:03,744 ERROR exception
Traceback (most recent call last):
  File "D:\Development\android_workspace\SC\scapp\views\information\khxxgl.py", line 374, in sc_manage_info
    db.session.commit()
  File "D:\Development\android_workspace\SC\virtualenv32\lib\site-packages\sqlalchemy\orm\scoping.py", line 149, in do
    return getattr(self.registry(), name)(*args, **kwargs)
  File "D:\Development\android_workspace\SC\virtualenv32\lib\site-packages\sqlalchemy\orm\session.py", line 721, in commit
    self.transaction.commit()
  File "D:\Development\android_workspace\SC\virtualenv32\lib\site-packages\sqlalchemy\orm\session.py", line 354, in commit
    self._prepare_impl()
  File "D:\Development\android_workspace\SC\virtualenv32\lib\site-packages\sqlalchemy\orm\session.py", line 334, in _prepare_impl
    self.session.flush()
  File "D:\Development\android_workspace\SC\virtualenv32\lib\site-packages\sqlalchemy\orm\session.py", line 1818, in flush
    self._flush(objects)
  File "D:\Development\android_workspace\SC\virtualenv32\lib\site-packages\sqlalchemy\orm\session.py", line 1936, in _flush
    transaction.rollback(_capture_exception=True)
  File "D:\Development\android_workspace\SC\virtualenv32\lib\site-packages\sqlalchemy\util\langhelpers.py", line 58, in __exit__
    compat.reraise(exc_type, exc_value, exc_tb)
  File "D:\Development\android_workspace\SC\virtualenv32\lib\site-packages\sqlalchemy\orm\session.py", line 1900, in _flush
    flush_context.execute()
  File "D:\Development\android_workspace\SC\virtualenv32\lib\site-packages\sqlalchemy\orm\unitofwork.py", line 372, in execute
    rec.execute(self)
  File "D:\Development\android_workspace\SC\virtualenv32\lib\site-packages\sqlalchemy\orm\unitofwork.py", line 525, in execute
    uow
  File "D:\Development\android_workspace\SC\virtualenv32\lib\site-packages\sqlalchemy\orm\persistence.py", line 64, in save_obj
    table, insert)
  File "D:\Development\android_workspace\SC\virtualenv32\lib\site-packages\sqlalchemy\orm\persistence.py", line 569, in _emit_insert_statements
    execute(statement, params)
  File "D:\Development\android_workspace\SC\virtualenv32\lib\site-packages\sqlalchemy\engine\base.py", line 662, in execute
    params)
  File "D:\Development\android_workspace\SC\virtualenv32\lib\site-packages\sqlalchemy\engine\base.py", line 761, in _execute_clauseelement
    compiled_sql, distilled_params
  File "D:\Development\android_workspace\SC\virtualenv32\lib\site-packages\sqlalchemy\engine\base.py", line 874, in _execute_context
    context)
  File "D:\Development\android_workspace\SC\virtualenv32\lib\site-packages\sqlalchemy\engine\base.py", line 1024, in _handle_dbapi_exception
    exc_info
  File "D:\Development\android_workspace\SC\virtualenv32\lib\site-packages\sqlalchemy\util\compat.py", line 195, in raise_from_cause
    reraise(type(exception), exception, tb=exc_tb)
  File "D:\Development\android_workspace\SC\virtualenv32\lib\site-packages\sqlalchemy\engine\base.py", line 867, in _execute_context
    context)
  File "D:\Development\android_workspace\SC\virtualenv32\lib\site-packages\sqlalchemy\engine\default.py", line 324, in do_execute
    cursor.execute(statement, parameters)
  File "D:\Development\android_workspace\SC\virtualenv32\lib\site-packages\MySQLdb\cursors.py", line 202, in execute
    self.errorhandler(self, exc, value)
  File "D:\Development\android_workspace\SC\virtualenv32\lib\site-packages\MySQLdb\connections.py", line 36, in defaulterrorhandler
    raise errorclass, errorvalue
OperationalError: (OperationalError) (1366, "Incorrect integer value: '' for column 'annual_income' at row 1") 'INSERT INTO sc_manage_info (business_name, industry, business_description, business_type, stake, business_address, annual_income, monthly_income, establish_date, employees, manager_name, credentials_type, credentials_no, credentials_org, belong_customer_type, belong_customer_value, create_user, create_date, modify_user, modify_date) VALUES (%s, %s, %s, %s, %s, %s, %s, %s, %s, %s, %s, %s, %s, %s, %s, %s, %s, %s, %s, %s)' ('\xe4\xb8\x9a\xe5\x8a\xa1', u'3', '', u'3', '100', '\xe7\xbb\x8f\xe8\x90\xa5\xe5\x9c\xb0\xe5\x9d\x80', u'', u'', u'2014-01-15', u'', u'\u8d23\u4efb\u4eba', u'4', '123', '\xe6\x9c\xba\xe5\x85\xb3\xe6\x9c\xba\xe5\x85\xb3', 'Individual', 11, 20L, datetime.datetime(2014, 1, 15, 14, 48, 3, 740000), 20L, datetime.datetime(2014, 1, 15, 14, 48, 3, 740000))
2014-01-15 14:59:27,572 ERROR exception
Traceback (most recent call last):
  File "D:\Development\android_workspace\SC\scapp\views\process\dksq.py", line 168, in new_dksq
    request.form.getlist('mybj%d' % i)[i],request.form.getlist('mylx%d' % i)[i],phone_db_list[i],
IndexError: list index out of range
2014-01-15 17:17:39,223 ERROR exception
Traceback (most recent call last):
  File "D:\Development\android_workspace\SC\scapp\views\process\dqdc.py", line 348, in credit_upload
    f.save(os.path.join(UPLOAD_FOLDER_ABS,'%d/%s' % (loan_apply_id,fname)))
  File "D:\Development\android_workspace\SC\virtualenv32\lib\site-packages\werkzeug\datastructures.py", line 2576, in save
    dst = open(dst, 'wb')
IOError: [Errno 2] No such file or directory: u'D:\\Development\\android_workspace\\SC\\scapp\\static\\upload\\26/\u5458\u5de5\u901a\u8baf\u5f55.xls'
2014-01-15 17:18:06,565 ERROR exception
Traceback (most recent call last):
  File "D:\Development\android_workspace\SC\scapp\views\process\dqdc.py", line 348, in credit_upload
    f.save(os.path.join(UPLOAD_FOLDER_ABS,'%d\\%s' % (loan_apply_id,fname)))
  File "D:\Development\android_workspace\SC\virtualenv32\lib\site-packages\werkzeug\datastructures.py", line 2576, in save
    dst = open(dst, 'wb')
IOError: [Errno 2] No such file or directory: u'D:\\Development\\android_workspace\\SC\\scapp\\static\\upload\\26\\\u5458\u5de5\u901a\u8baf\u5f55.xls'
2014-01-15 17:20:06,638 ERROR exception
Traceback (most recent call last):
  File "D:\Development\android_workspace\SC\scapp\views\process\dqdc.py", line 348, in credit_upload
    f.save(os.path.join(UPLOAD_FOLDER_ABS,'%d\\%s' % (loan_apply_id,fname)))
  File "D:\Development\android_workspace\SC\virtualenv32\lib\site-packages\werkzeug\datastructures.py", line 2576, in save
    dst = open(dst, 'wb')
IOError: [Errno 2] No such file or directory: u'D:\\Development\\android_workspace\\SC\\scapp\\static\\upload\\26\\1379654908892.jpg'
2014-01-15 17:30:34,092 ERROR exception
Traceback (most recent call last):
  File "D:\Development\android_workspace\SC\scapp\views\process\dqdc.py", line 348, in credit_upload
    print os.path.join(UPLOAD_FOLDER_ABS,loan_apply_id)
  File "D:\Development\android_workspace\SC\virtualenv32\lib\ntpath.py", line 73, in join
    elif isabs(b):
  File "D:\Development\android_workspace\SC\virtualenv32\lib\ntpath.py", line 57, in isabs
    s = splitdrive(s)[1]
  File "D:\Development\android_workspace\SC\virtualenv32\lib\ntpath.py", line 125, in splitdrive
    if p[1:2] == ':':
TypeError: 'int' object has no attribute '__getitem__'
2014-01-16 16:21:09,806 ERROR exception
Traceback (most recent call last):
  File "D:\Development\android_workspace\SC\scapp\views\process\dqdc.py", line 349, in credit_upload
    os.mkdir(os.path.join(UPLOAD_FOLDER_ABS,str(loan_apply_id)))
WindowsError: [Error 183] : 'D:\\Development\\android_workspace\\SC\\scapp\\static\\upload\\26'
2014-01-16 16:35:42,625 ERROR exception
Traceback (most recent call last):
  File "D:\Development\android_workspace\SC\scapp\views\process\dqdc.py", line 349, in credit_upload
    if os.path.exists(os.path.join(UPLOAD_FOLDER_ABS,str(loan_apply_id))) == false:
NameError: global name 'false' is not defined
2014-03-05 16:01:36,181 ERROR exception
Traceback (most recent call last):
  File "/Users/johhny/project/xhsc_git/scapp/views/process/dqdc.py", line 165, in edit_dqdcWd_jbqk
    db.session.commit()
  File "/Users/johhny/project/xhsc/lib/python2.7/site-packages/sqlalchemy/orm/scoping.py", line 149, in do
    return getattr(self.registry(), name)(*args, **kwargs)
  File "/Users/johhny/project/xhsc/lib/python2.7/site-packages/sqlalchemy/orm/session.py", line 721, in commit
    self.transaction.commit()
  File "/Users/johhny/project/xhsc/lib/python2.7/site-packages/sqlalchemy/orm/session.py", line 354, in commit
    self._prepare_impl()
  File "/Users/johhny/project/xhsc/lib/python2.7/site-packages/sqlalchemy/orm/session.py", line 334, in _prepare_impl
    self.session.flush()
  File "/Users/johhny/project/xhsc/lib/python2.7/site-packages/sqlalchemy/orm/session.py", line 1818, in flush
    self._flush(objects)
  File "/Users/johhny/project/xhsc/lib/python2.7/site-packages/sqlalchemy/orm/session.py", line 1936, in _flush
    transaction.rollback(_capture_exception=True)
  File "/Users/johhny/project/xhsc/lib/python2.7/site-packages/sqlalchemy/util/langhelpers.py", line 58, in __exit__
    compat.reraise(exc_type, exc_value, exc_tb)
  File "/Users/johhny/project/xhsc/lib/python2.7/site-packages/sqlalchemy/orm/session.py", line 1900, in _flush
    flush_context.execute()
  File "/Users/johhny/project/xhsc/lib/python2.7/site-packages/sqlalchemy/orm/unitofwork.py", line 372, in execute
    rec.execute(self)
  File "/Users/johhny/project/xhsc/lib/python2.7/site-packages/sqlalchemy/orm/unitofwork.py", line 525, in execute
    uow
  File "/Users/johhny/project/xhsc/lib/python2.7/site-packages/sqlalchemy/orm/persistence.py", line 64, in save_obj
    table, insert)
  File "/Users/johhny/project/xhsc/lib/python2.7/site-packages/sqlalchemy/orm/persistence.py", line 569, in _emit_insert_statements
    execute(statement, params)
  File "/Users/johhny/project/xhsc/lib/python2.7/site-packages/sqlalchemy/engine/base.py", line 662, in execute
    params)
  File "/Users/johhny/project/xhsc/lib/python2.7/site-packages/sqlalchemy/engine/base.py", line 761, in _execute_clauseelement
    compiled_sql, distilled_params
  File "/Users/johhny/project/xhsc/lib/python2.7/site-packages/sqlalchemy/engine/base.py", line 874, in _execute_context
    context)
  File "/Users/johhny/project/xhsc/lib/python2.7/site-packages/sqlalchemy/engine/base.py", line 1024, in _handle_dbapi_exception
    exc_info
  File "/Users/johhny/project/xhsc/lib/python2.7/site-packages/sqlalchemy/util/compat.py", line 195, in raise_from_cause
    reraise(type(exception), exception, tb=exc_tb)
  File "/Users/johhny/project/xhsc/lib/python2.7/site-packages/sqlalchemy/engine/base.py", line 867, in _execute_context
    context)
  File "/Users/johhny/project/xhsc/lib/python2.7/site-packages/sqlalchemy/engine/default.py", line 324, in do_execute
    cursor.execute(statement, parameters)
  File "/Users/johhny/project/xhsc/lib/python2.7/site-packages/MySQLdb/cursors.py", line 201, in execute
    self.errorhandler(self, exc, value)
  File "/Users/johhny/project/xhsc/lib/python2.7/site-packages/MySQLdb/connections.py", line 36, in defaulterrorhandler
    raise errorclass, errorvalue
OperationalError: (OperationalError) (1292, "Incorrect date value: '1' for column 'recommended_deadline' at row 1") 'INSERT INTO sc_riskanalysis_and_findings (loan_apply_id, analysis_conclusion, amount_recommended, recommended_deadline, recommended_rates, monthly_repayment_amount, recommended_way_of_security, income_ratio, survey_signature, survey_date, verification, others, bool_grant, amount, deadline, rates, monthly_repayment, approve_reason, refuse_reason, other_deliberations, positive, opposite, create_user, create_date, modify_user, modify_date) VALUES (%s, %s, %s, %s, %s, %s, %s, %s, %s, %s, %s, %s, %s, %s, %s, %s, %s, %s, %s, %s, %s, %s, %s, %s, %s, %s)' (53, '', '', u'1', '', '', '', '', '', u'2014-03-05', 0, '', '1', '1000000', '6', '1.15', '66767', '', '', '', '', '', 19L, datetime.datetime(2014, 3, 5, 16, 1, 36, 173189), 19L, datetime.datetime(2014, 3, 5, 16, 1, 36, 173229))
2014-03-05 16:03:06,035 ERROR exception
Traceback (most recent call last):
  File "/Users/johhny/project/xhsc_git/scapp/views/process/dqdc.py", line 165, in edit_dqdcWd_jbqk
    db.session.commit()
  File "/Users/johhny/project/xhsc/lib/python2.7/site-packages/sqlalchemy/orm/scoping.py", line 149, in do
    return getattr(self.registry(), name)(*args, **kwargs)
  File "/Users/johhny/project/xhsc/lib/python2.7/site-packages/sqlalchemy/orm/session.py", line 721, in commit
    self.transaction.commit()
  File "/Users/johhny/project/xhsc/lib/python2.7/site-packages/sqlalchemy/orm/session.py", line 354, in commit
    self._prepare_impl()
  File "/Users/johhny/project/xhsc/lib/python2.7/site-packages/sqlalchemy/orm/session.py", line 334, in _prepare_impl
    self.session.flush()
  File "/Users/johhny/project/xhsc/lib/python2.7/site-packages/sqlalchemy/orm/session.py", line 1818, in flush
    self._flush(objects)
  File "/Users/johhny/project/xhsc/lib/python2.7/site-packages/sqlalchemy/orm/session.py", line 1936, in _flush
    transaction.rollback(_capture_exception=True)
  File "/Users/johhny/project/xhsc/lib/python2.7/site-packages/sqlalchemy/util/langhelpers.py", line 58, in __exit__
    compat.reraise(exc_type, exc_value, exc_tb)
  File "/Users/johhny/project/xhsc/lib/python2.7/site-packages/sqlalchemy/orm/session.py", line 1900, in _flush
    flush_context.execute()
  File "/Users/johhny/project/xhsc/lib/python2.7/site-packages/sqlalchemy/orm/unitofwork.py", line 372, in execute
    rec.execute(self)
  File "/Users/johhny/project/xhsc/lib/python2.7/site-packages/sqlalchemy/orm/unitofwork.py", line 525, in execute
    uow
  File "/Users/johhny/project/xhsc/lib/python2.7/site-packages/sqlalchemy/orm/persistence.py", line 64, in save_obj
    table, insert)
  File "/Users/johhny/project/xhsc/lib/python2.7/site-packages/sqlalchemy/orm/persistence.py", line 569, in _emit_insert_statements
    execute(statement, params)
  File "/Users/johhny/project/xhsc/lib/python2.7/site-packages/sqlalchemy/engine/base.py", line 662, in execute
    params)
  File "/Users/johhny/project/xhsc/lib/python2.7/site-packages/sqlalchemy/engine/base.py", line 761, in _execute_clauseelement
    compiled_sql, distilled_params
  File "/Users/johhny/project/xhsc/lib/python2.7/site-packages/sqlalchemy/engine/base.py", line 874, in _execute_context
    context)
  File "/Users/johhny/project/xhsc/lib/python2.7/site-packages/sqlalchemy/engine/base.py", line 1024, in _handle_dbapi_exception
    exc_info
  File "/Users/johhny/project/xhsc/lib/python2.7/site-packages/sqlalchemy/util/compat.py", line 195, in raise_from_cause
    reraise(type(exception), exception, tb=exc_tb)
  File "/Users/johhny/project/xhsc/lib/python2.7/site-packages/sqlalchemy/engine/base.py", line 867, in _execute_context
    context)
  File "/Users/johhny/project/xhsc/lib/python2.7/site-packages/sqlalchemy/engine/default.py", line 324, in do_execute
    cursor.execute(statement, parameters)
  File "/Users/johhny/project/xhsc/lib/python2.7/site-packages/MySQLdb/cursors.py", line 201, in execute
    self.errorhandler(self, exc, value)
  File "/Users/johhny/project/xhsc/lib/python2.7/site-packages/MySQLdb/connections.py", line 36, in defaulterrorhandler
    raise errorclass, errorvalue
OperationalError: (OperationalError) (1292, "Incorrect date value: '1' for column 'recommended_deadline' at row 1") 'INSERT INTO sc_riskanalysis_and_findings (loan_apply_id, analysis_conclusion, amount_recommended, recommended_deadline, recommended_rates, monthly_repayment_amount, recommended_way_of_security, income_ratio, survey_signature, survey_date, verification, others, bool_grant, amount, deadline, rates, monthly_repayment, approve_reason, refuse_reason, other_deliberations, positive, opposite, create_user, create_date, modify_user, modify_date) VALUES (%s, %s, %s, %s, %s, %s, %s, %s, %s, %s, %s, %s, %s, %s, %s, %s, %s, %s, %s, %s, %s, %s, %s, %s, %s, %s)' (53, '', '', u'1', '', '', '', '', '', u'2014-03-05', 0, '', '1', '10000000', '10', '1.15', '2131', '', '', '', '', '', 19L, datetime.datetime(2014, 3, 5, 16, 3, 6, 28033), 19L, datetime.datetime(2014, 3, 5, 16, 3, 6, 28059))
2014-03-05 16:06:27,188 ERROR exception
Traceback (most recent call last):
  File "/Users/johhny/project/xhsc_git/scapp/views/process/dqdc.py", line 165, in edit_dqdcWd_jbqk
    db.session.commit()
  File "/Users/johhny/project/xhsc/lib/python2.7/site-packages/sqlalchemy/orm/scoping.py", line 149, in do
    return getattr(self.registry(), name)(*args, **kwargs)
  File "/Users/johhny/project/xhsc/lib/python2.7/site-packages/sqlalchemy/orm/session.py", line 721, in commit
    self.transaction.commit()
  File "/Users/johhny/project/xhsc/lib/python2.7/site-packages/sqlalchemy/orm/session.py", line 354, in commit
    self._prepare_impl()
  File "/Users/johhny/project/xhsc/lib/python2.7/site-packages/sqlalchemy/orm/session.py", line 334, in _prepare_impl
    self.session.flush()
  File "/Users/johhny/project/xhsc/lib/python2.7/site-packages/sqlalchemy/orm/session.py", line 1818, in flush
    self._flush(objects)
  File "/Users/johhny/project/xhsc/lib/python2.7/site-packages/sqlalchemy/orm/session.py", line 1936, in _flush
    transaction.rollback(_capture_exception=True)
  File "/Users/johhny/project/xhsc/lib/python2.7/site-packages/sqlalchemy/util/langhelpers.py", line 58, in __exit__
    compat.reraise(exc_type, exc_value, exc_tb)
  File "/Users/johhny/project/xhsc/lib/python2.7/site-packages/sqlalchemy/orm/session.py", line 1900, in _flush
    flush_context.execute()
  File "/Users/johhny/project/xhsc/lib/python2.7/site-packages/sqlalchemy/orm/unitofwork.py", line 372, in execute
    rec.execute(self)
  File "/Users/johhny/project/xhsc/lib/python2.7/site-packages/sqlalchemy/orm/unitofwork.py", line 525, in execute
    uow
  File "/Users/johhny/project/xhsc/lib/python2.7/site-packages/sqlalchemy/orm/persistence.py", line 64, in save_obj
    table, insert)
  File "/Users/johhny/project/xhsc/lib/python2.7/site-packages/sqlalchemy/orm/persistence.py", line 569, in _emit_insert_statements
    execute(statement, params)
  File "/Users/johhny/project/xhsc/lib/python2.7/site-packages/sqlalchemy/engine/base.py", line 662, in execute
    params)
  File "/Users/johhny/project/xhsc/lib/python2.7/site-packages/sqlalchemy/engine/base.py", line 761, in _execute_clauseelement
    compiled_sql, distilled_params
  File "/Users/johhny/project/xhsc/lib/python2.7/site-packages/sqlalchemy/engine/base.py", line 874, in _execute_context
    context)
  File "/Users/johhny/project/xhsc/lib/python2.7/site-packages/sqlalchemy/engine/base.py", line 1024, in _handle_dbapi_exception
    exc_info
  File "/Users/johhny/project/xhsc/lib/python2.7/site-packages/sqlalchemy/util/compat.py", line 195, in raise_from_cause
    reraise(type(exception), exception, tb=exc_tb)
  File "/Users/johhny/project/xhsc/lib/python2.7/site-packages/sqlalchemy/engine/base.py", line 867, in _execute_context
    context)
  File "/Users/johhny/project/xhsc/lib/python2.7/site-packages/sqlalchemy/engine/default.py", line 324, in do_execute
    cursor.execute(statement, parameters)
  File "/Users/johhny/project/xhsc/lib/python2.7/site-packages/MySQLdb/cursors.py", line 201, in execute
    self.errorhandler(self, exc, value)
  File "/Users/johhny/project/xhsc/lib/python2.7/site-packages/MySQLdb/connections.py", line 36, in defaulterrorhandler
    raise errorclass, errorvalue
OperationalError: (OperationalError) (1292, "Incorrect date value: '9' for column 'recommended_deadline' at row 1") 'INSERT INTO sc_riskanalysis_and_findings (loan_apply_id, analysis_conclusion, amount_recommended, recommended_deadline, recommended_rates, monthly_repayment_amount, recommended_way_of_security, income_ratio, survey_signature, survey_date, verification, others, bool_grant, amount, deadline, rates, monthly_repayment, approve_reason, refuse_reason, other_deliberations, positive, opposite, create_user, create_date, modify_user, modify_date) VALUES (%s, %s, %s, %s, %s, %s, %s, %s, %s, %s, %s, %s, %s, %s, %s, %s, %s, %s, %s, %s, %s, %s, %s, %s, %s, %s)' (53, '', '1000000', u'9', '1.15', '11231', '', '', '', u'2014-03-05', 0, '', '1', '1000000', '8', '1.15', '22131', '', '', '', '', '', 19L, datetime.datetime(2014, 3, 5, 16, 6, 27, 183079), 19L, datetime.datetime(2014, 3, 5, 16, 6, 27, 183109))
2014-03-05 16:10:31,598 ERROR exception
Traceback (most recent call last):
  File "/Users/johhny/project/xhsc_git/scapp/views/process/dqdc.py", line 261, in edit_dqdcXed_jbqk
    db.session.commit()
  File "/Users/johhny/project/xhsc/lib/python2.7/site-packages/sqlalchemy/orm/scoping.py", line 149, in do
    return getattr(self.registry(), name)(*args, **kwargs)
  File "/Users/johhny/project/xhsc/lib/python2.7/site-packages/sqlalchemy/orm/session.py", line 721, in commit
    self.transaction.commit()
  File "/Users/johhny/project/xhsc/lib/python2.7/site-packages/sqlalchemy/orm/session.py", line 354, in commit
    self._prepare_impl()
  File "/Users/johhny/project/xhsc/lib/python2.7/site-packages/sqlalchemy/orm/session.py", line 334, in _prepare_impl
    self.session.flush()
  File "/Users/johhny/project/xhsc/lib/python2.7/site-packages/sqlalchemy/orm/session.py", line 1818, in flush
    self._flush(objects)
  File "/Users/johhny/project/xhsc/lib/python2.7/site-packages/sqlalchemy/orm/session.py", line 1936, in _flush
    transaction.rollback(_capture_exception=True)
  File "/Users/johhny/project/xhsc/lib/python2.7/site-packages/sqlalchemy/util/langhelpers.py", line 58, in __exit__
    compat.reraise(exc_type, exc_value, exc_tb)
  File "/Users/johhny/project/xhsc/lib/python2.7/site-packages/sqlalchemy/orm/session.py", line 1900, in _flush
    flush_context.execute()
  File "/Users/johhny/project/xhsc/lib/python2.7/site-packages/sqlalchemy/orm/unitofwork.py", line 372, in execute
    rec.execute(self)
  File "/Users/johhny/project/xhsc/lib/python2.7/site-packages/sqlalchemy/orm/unitofwork.py", line 525, in execute
    uow
  File "/Users/johhny/project/xhsc/lib/python2.7/site-packages/sqlalchemy/orm/persistence.py", line 64, in save_obj
    table, insert)
  File "/Users/johhny/project/xhsc/lib/python2.7/site-packages/sqlalchemy/orm/persistence.py", line 569, in _emit_insert_statements
    execute(statement, params)
  File "/Users/johhny/project/xhsc/lib/python2.7/site-packages/sqlalchemy/engine/base.py", line 662, in execute
    params)
  File "/Users/johhny/project/xhsc/lib/python2.7/site-packages/sqlalchemy/engine/base.py", line 761, in _execute_clauseelement
    compiled_sql, distilled_params
  File "/Users/johhny/project/xhsc/lib/python2.7/site-packages/sqlalchemy/engine/base.py", line 874, in _execute_context
    context)
  File "/Users/johhny/project/xhsc/lib/python2.7/site-packages/sqlalchemy/engine/base.py", line 1024, in _handle_dbapi_exception
    exc_info
  File "/Users/johhny/project/xhsc/lib/python2.7/site-packages/sqlalchemy/util/compat.py", line 195, in raise_from_cause
    reraise(type(exception), exception, tb=exc_tb)
  File "/Users/johhny/project/xhsc/lib/python2.7/site-packages/sqlalchemy/engine/base.py", line 867, in _execute_context
    context)
  File "/Users/johhny/project/xhsc/lib/python2.7/site-packages/sqlalchemy/engine/default.py", line 324, in do_execute
    cursor.execute(statement, parameters)
  File "/Users/johhny/project/xhsc/lib/python2.7/site-packages/MySQLdb/cursors.py", line 201, in execute
    self.errorhandler(self, exc, value)
  File "/Users/johhny/project/xhsc/lib/python2.7/site-packages/MySQLdb/connections.py", line 36, in defaulterrorhandler
    raise errorclass, errorvalue
OperationalError: (OperationalError) (1292, "Incorrect date value: '1' for column 'recommended_deadline' at row 1") 'INSERT INTO sc_riskanalysis_and_findings (loan_apply_id, analysis_conclusion, amount_recommended, recommended_deadline, recommended_rates, monthly_repayment_amount, recommended_way_of_security, income_ratio, survey_signature, survey_date, verification, others, bool_grant, amount, deadline, rates, monthly_repayment, approve_reason, refuse_reason, other_deliberations, positive, opposite, create_user, create_date, modify_user, modify_date) VALUES (%s, %s, %s, %s, %s, %s, %s, %s, %s, %s, %s, %s, %s, %s, %s, %s, %s, %s, %s, %s, %s, %s, %s, %s, %s, %s)' (54, '', '', u'1', '', '', '', '', '', u'2014-03-05', 511, '', '1', '1000000', '10', '1.15', '10000', '', '', '', '', '', 20L, datetime.datetime(2014, 3, 5, 16, 10, 31, 591581), 20L, datetime.datetime(2014, 3, 5, 16, 10, 31, 591604))
2014-03-05 17:05:33,657 ERROR exception
Traceback (most recent call last):
  File "/Users/johhny/project/xhsc_git/scapp/views/process/dkfk.py", line 110, in edit_dkfk
    repayment_plan_new = SC_Repayment_Plan(id,request.form['repayment_type'],request.form['amount'],
  File "/Users/johhny/project/xhsc/lib/python2.7/site-packages/werkzeug/datastructures.py", line 391, in __getitem__
    raise exceptions.BadRequestKeyError(key)
BadRequestKeyError: 400: Bad Request
2014-03-05 17:06:47,184 ERROR exception
Traceback (most recent call last):
  File "/Users/johhny/project/xhsc_git/scapp/views/process/dkfk.py", line 110, in edit_dkfk
    repayment_plan_new = SC_Repayment_Plan(id,request.form['repayment_type'],request.form['amount'],
  File "/Users/johhny/project/xhsc/lib/python2.7/site-packages/werkzeug/datastructures.py", line 391, in __getitem__
    raise exceptions.BadRequestKeyError(key)
BadRequestKeyError: 400: Bad Request
2014-03-05 17:16:43,787 ERROR exception
Traceback (most recent call last):
  File "/Users/johhny/project/xhsc_git/scapp/views/process/dkfk.py", line 110, in edit_dkfk
    repayment_plan_new = SC_Repayment_Plan(id,request.form['repayment_type'],request.form['amount'],
  File "/Users/johhny/project/xhsc/lib/python2.7/site-packages/werkzeug/datastructures.py", line 391, in __getitem__
    raise exceptions.BadRequestKeyError(key)
BadRequestKeyError: 400: Bad Request
